peatio:amqp:order_processor:1: process with pid 5655 started.
I, [2014-06-30T16:37:01.621212 #5655]  INFO -- : Connected to AMQP broker (prefetch: default)
/home/deploy/.rbenv/versions/2.1.2/lib/ruby/gems/2.1.0/gems/bunny-1.2.1/lib/bunny/channel.rb:1883:in `raise_if_continuation_resulted_in_a_channel_error!': ACCESS_REFUSED - access to queue 'peatio.order.processor' in vhost '/' refused for user 'netwareboss' (Bunny::AccessRefused)
	from /home/deploy/.rbenv/versions/2.1.2/lib/ruby/gems/2.1.0/gems/bunny-1.2.1/lib/bunny/channel.rb:974:in `queue_declare'
	from /home/deploy/.rbenv/versions/2.1.2/lib/ruby/gems/2.1.0/gems/bunny-1.2.1/lib/bunny/queue.rb:358:in `declare!'
	from /home/deploy/.rbenv/versions/2.1.2/lib/ruby/gems/2.1.0/gems/bunny-1.2.1/lib/bunny/queue.rb:56:in `initialize'
	from /home/deploy/.rbenv/versions/2.1.2/lib/ruby/gems/2.1.0/gems/bunny-1.2.1/lib/bunny/channel.rb:401:in `new'
	from /home/deploy/.rbenv/versions/2.1.2/lib/ruby/gems/2.1.0/gems/bunny-1.2.1/lib/bunny/channel.rb:401:in `queue'
	from /home/deploy/peatio/current/lib/daemons/amqp_daemon.rb:37:in `block in <top (required)>'
	from /home/deploy/peatio/current/lib/daemons/amqp_daemon.rb:35:in `each'
	from /home/deploy/peatio/current/lib/daemons/amqp_daemon.rb:35:in `<top (required)>'
	from /home/deploy/.rbenv/versions/2.1.2/lib/ruby/gems/2.1.0/gems/daemons-1.1.9/lib/daemons/application.rb:203:in `load'
	from /home/deploy/.rbenv/versions/2.1.2/lib/ruby/gems/2.1.0/gems/daemons-1.1.9/lib/daemons/application.rb:203:in `start_load'
	from /home/deploy/.rbenv/versions/2.1.2/lib/ruby/gems/2.1.0/gems/daemons-1.1.9/lib/daemons/application.rb:298:in `start'
	from /home/deploy/.rbenv/versions/2.1.2/lib/ruby/gems/2.1.0/gems/daemons-1.1.9/lib/daemons/controller.rb:70:in `run'
	from /home/deploy/.rbenv/versions/2.1.2/lib/ruby/gems/2.1.0/gems/daemons-1.1.9/lib/daemons.rb:147:in `block in run'
	from /home/deploy/.rbenv/versions/2.1.2/lib/ruby/gems/2.1.0/gems/daemons-1.1.9/lib/daemons/cmdline.rb:109:in `call'
	from /home/deploy/.rbenv/versions/2.1.2/lib/ruby/gems/2.1.0/gems/daemons-1.1.9/lib/daemons/cmdline.rb:109:in `catch_exceptions'
	from /home/deploy/.rbenv/versions/2.1.2/lib/ruby/gems/2.1.0/gems/daemons-1.1.9/lib/daemons.rb:146:in `run'
	from /home/deploy/.rbenv/versions/2.1.2/lib/ruby/gems/2.1.0/gems/daemons-rails-1.2.1/lib/daemons/rails.rb:16:in `run'
	from lib/daemons/order_processor_ctl:17:in `block in <main>'
	from lib/daemons/order_processor_ctl:7:in `times'
	from lib/daemons/order_processor_ctl:7:in `<main>'
peatio:amqp:order_processor:1: process with pid 2357 started.
E, [2014-06-30T18:32:38.741737 #2357] ERROR -- #<Bunny::Session:69847672246880 guest@59.127.216.102:5672, vhost=/>: Authentication with RabbitMQ failed: 403 ACCESS_REFUSED - Login was refused using authentication mechanism PLAIN. For details see the broker logfile.
/home/deploy/.rbenv/versions/2.1.2/lib/ruby/gems/2.1.0/gems/bunny-1.2.1/lib/bunny/session.rb:960:in `open_connection': Authentication with RabbitMQ failed. Please check your connection settings. Username: guest, vhost: /, password length: 5 (Bunny::AuthenticationFailureError)
	from /home/deploy/.rbenv/versions/2.1.2/lib/ruby/gems/2.1.0/gems/bunny-1.2.1/lib/bunny/session.rb:255:in `start'
	from /home/deploy/peatio/current/lib/daemons/amqp_daemon.rb:17:in `<top (required)>'
	from /home/deploy/.rbenv/versions/2.1.2/lib/ruby/gems/2.1.0/gems/daemons-1.1.9/lib/daemons/application.rb:203:in `load'
	from /home/deploy/.rbenv/versions/2.1.2/lib/ruby/gems/2.1.0/gems/daemons-1.1.9/lib/daemons/application.rb:203:in `start_load'
	from /home/deploy/.rbenv/versions/2.1.2/lib/ruby/gems/2.1.0/gems/daemons-1.1.9/lib/daemons/application.rb:298:in `start'
	from /home/deploy/.rbenv/versions/2.1.2/lib/ruby/gems/2.1.0/gems/daemons-1.1.9/lib/daemons/controller.rb:70:in `run'
	from /home/deploy/.rbenv/versions/2.1.2/lib/ruby/gems/2.1.0/gems/daemons-1.1.9/lib/daemons.rb:147:in `block in run'
	from /home/deploy/.rbenv/versions/2.1.2/lib/ruby/gems/2.1.0/gems/daemons-1.1.9/lib/daemons/cmdline.rb:109:in `call'
	from /home/deploy/.rbenv/versions/2.1.2/lib/ruby/gems/2.1.0/gems/daemons-1.1.9/lib/daemons/cmdline.rb:109:in `catch_exceptions'
	from /home/deploy/.rbenv/versions/2.1.2/lib/ruby/gems/2.1.0/gems/daemons-1.1.9/lib/daemons.rb:146:in `run'
	from /home/deploy/.rbenv/versions/2.1.2/lib/ruby/gems/2.1.0/gems/daemons-rails-1.2.1/lib/daemons/rails.rb:16:in `run'
	from lib/daemons/order_processor_ctl:17:in `block in <main>'
	from lib/daemons/order_processor_ctl:7:in `times'
	from lib/daemons/order_processor_ctl:7:in `<main>'
peatio:amqp:order_processor:1: process with pid 2299 started.
I, [2014-06-30T19:21:20.983444 #2299]  INFO -- : Connected to AMQP broker (prefetch: default)
